2023-02-03 01:35:28,223 __main__ INFO -- Get or create the cluster --
2023-02-03 01:35:28,224 TADA INFO starting test `store_sos_lists_test`
2023-02-03 01:35:28,224 TADA INFO   test-id: baaa1a948e80fe3cec3d3c0ebb02bba89e9845ef45b4f3712716e2fccbec8e09
2023-02-03 01:35:28,224 TADA INFO   test-suite: LDMSD
2023-02-03 01:35:28,224 TADA INFO   test-name: store_sos_lists_test
2023-02-03 01:35:28,224 TADA INFO   test-user: narate
2023-02-03 01:35:28,224 TADA INFO   commit-id: 7d1ff1aeef7696d3ecea60a637cb59a0c07a7a00
2023-02-03 01:35:36,041 __main__ INFO Waiting ... for all LDMSDs to start
2023-02-03 01:35:39,924 __main__ INFO All sampler daemons are up.
2023-02-03 01:35:40,030 TADA INFO assertion 1, aggregator with store_sos has started properly.: agg_sos.check_ldmsd(), passed
2023-02-03 01:35:40,150 TADA INFO assertion 2, aggregator with store_csv has started properly.: agg_csv.check_ldmsd(), passed
2023-02-03 01:35:51,241 TADA INFO assertion 3, store_sos is storing data.: agg.file_exists/store/sos/record_record_record, failed
Traceback (most recent call last):
  File "store_list_record_test", line 427, in <module>
    test.assert_test(SOS_DATABASE_CREATED, result, reason)
  File "/home/narate/cron/ldms-test/TADA.py", line 157, in assert_test
    raise AssertionException(self.test_desc + ", " + cond_str + ": FAILED")
TADA.AssertionException: Test store_sos storing lists, agg.file_exists/store/sos/record_record_record: FAILED
2023-02-03 01:35:51,242 TADA INFO assertion 4, store_sos stores data correctly.: skipped
2023-02-03 01:35:51,243 TADA INFO assertion 5, store_sos stores data after restarted correctly.: skipped
2023-02-03 01:35:51,243 TADA INFO assertion 6, store_csv is storing data.: skipped
2023-02-03 01:35:51,243 TADA INFO assertion 7, store_csv stores data correctly.: skipped
2023-02-03 01:35:51,244 TADA INFO assertion 8, store_csv stores data after restarted correctly.: skipped
2023-02-03 01:35:51,244 TADA INFO test store_sos_lists_test ended
