2023-07-05 01:11:40,129 __main__ INFO -- Get or create the cluster --
2023-07-05 01:11:40,129 TADA INFO starting test `updtr_add test`
2023-07-05 01:11:40,129 TADA INFO   test-id: 7c0a46dc5bab895da5f5fc8b8b928486631b6c711148965682247e082b3b0f41
2023-07-05 01:11:40,129 TADA INFO   test-suite: LDMSD
2023-07-05 01:11:40,130 TADA INFO   test-name: updtr_add test
2023-07-05 01:11:40,130 TADA INFO   test-user: narate
2023-07-05 01:11:40,130 TADA INFO   commit-id: 636a1c6eed94acbb98f830d7507cbfe1ed9a92a0
2023-07-05 01:11:48,092 __main__ INFO -- Start daemons --
Traceback (most recent call last):
  File "/usr/lib/python3.6/site-packages/docker/api/client.py", line 261, in _raise_for_status
    response.raise_for_status()
  File "/usr/lib/python3.6/site-packages/requests/models.py", line 941, in raise_for_status
    raise HTTPError(http_error_msg, response=self)
requests.exceptions.HTTPError: 409 Client Error: Conflict for url: http+docker://localhost/v1.35/containers/928bf7a73ff9e947ac754532fe932b5d44d5e62ea4422184f7c8056c94c91e0c/exec

During handling of the above exception, another exception occurred:

Traceback (most recent call last):
  File "updtr_add_test", line 255, in <module>
    cluster.start_daemons()
  File "/home/narate/cron/ldms-test/LDMS_Test.py", line 1998, in start_daemons
    cont.start_daemons()
  File "/home/narate/cron/ldms-test/LDMS_Test.py", line 1260, in start_daemons
    fn(**daemon)
  File "/home/narate/cron/ldms-test/LDMS_Test.py", line 1003, in start_ldmsd
    cond_timedwait(_check_listen, 5)
  File "/home/narate/cron/ldms-test/LDMS_Test.py", line 2604, in cond_timedwait
    if cond():
  File "/home/narate/cron/ldms-test/LDMS_Test.py", line 1001, in _check_listen
    rc, out = self.exec_run(grp_cmd)
  File "/home/narate/cron/ldms-test/runtime/docker.py", line 144, in exec_run
    return self._exec_run(cmd, environment=env, user=user)
  File "/home/narate/cron/ldms-test/runtime/docker.py", line 148, in _exec_run
    (rc, out) = self.obj.exec_run(*args, **kwargs)
  File "/usr/lib/python3.6/site-packages/docker/models/containers.py", line 196, in exec_run
    workdir=workdir,
  File "/usr/lib/python3.6/site-packages/docker/utils/decorators.py", line 19, in wrapped
    return f(self, resource_id, *args, **kwargs)
  File "/usr/lib/python3.6/site-packages/docker/api/exec_api.py", line 80, in exec_create
    return self._result(res, True)
  File "/usr/lib/python3.6/site-packages/docker/api/client.py", line 267, in _result
    self._raise_for_status(response)
  File "/usr/lib/python3.6/site-packages/docker/api/client.py", line 263, in _raise_for_status
    raise create_api_error_from_http_exception(e)
  File "/usr/lib/python3.6/site-packages/docker/errors.py", line 31, in create_api_error_from_http_exception
    raise cls(e, response=response, explanation=explanation)
docker.errors.APIError: 409 Client Error: Conflict ("Container 928bf7a73ff9e947ac754532fe932b5d44d5e62ea4422184f7c8056c94c91e0c is not running")
2023-07-05 01:11:50,276 TADA INFO assertion 1, Add an updater with a negative interval: skipped
2023-07-05 01:11:50,276 TADA INFO assertion 2, Add an updater with a zero interval: skipped
2023-07-05 01:11:50,276 TADA INFO assertion 3, Add an updater with an alphabet interval: skipped
2023-07-05 01:11:50,277 TADA INFO assertion 4, Add an updater with a negative offset: skipped
2023-07-05 01:11:50,277 TADA INFO assertion 5, Add an updater with an alphabet offset: skipped
2023-07-05 01:11:50,277 TADA INFO assertion 6, Add an updater without an offset: skipped
2023-07-05 01:11:50,277 TADA INFO assertion 7, Add an updater with a valid offset: skipped
2023-07-05 01:11:50,277 TADA INFO assertion 8, Add an updater with an existing name: skipped
2023-07-05 01:11:50,277 TADA INFO test updtr_add test ended
