2023-07-08 00:58:19,913 __main__ INFO -- Get or create the cluster --
2023-07-08 00:58:19,913 TADA INFO starting test `updtr_add test`
2023-07-08 00:58:19,913 TADA INFO   test-id: 4c43fa5ba815dbf4e1288cecc58d853ae4a078f193079d25bd8a061f3c223436
2023-07-08 00:58:19,913 TADA INFO   test-suite: LDMSD
2023-07-08 00:58:19,913 TADA INFO   test-name: updtr_add test
2023-07-08 00:58:19,913 TADA INFO   test-user: narate
2023-07-08 00:58:19,913 TADA INFO   commit-id: 636a1c6eed94acbb98f830d7507cbfe1ed9a92a0
2023-07-08 00:58:28,346 __main__ INFO -- Start daemons --
Traceback (most recent call last):
  File "/usr/lib/python3.6/site-packages/docker/api/client.py", line 261, in _raise_for_status
    response.raise_for_status()
  File "/usr/lib/python3.6/site-packages/requests/models.py", line 941, in raise_for_status
    raise HTTPError(http_error_msg, response=self)
requests.exceptions.HTTPError: 500 Server Error: Internal Server Error for url: http+docker://localhost/v1.35/exec/655c7a553f9ddfc9f001dc77497d6e1627634b35c759a2f4df18bb9aea12560c/start

During handling of the above exception, another exception occurred:

Traceback (most recent call last):
  File "updtr_add_test", line 255, in <module>
    cluster.start_daemons()
  File "/home/narate/cron/ldms-test/LDMS_Test.py", line 1998, in start_daemons
    cont.start_daemons()
  File "/home/narate/cron/ldms-test/LDMS_Test.py", line 1260, in start_daemons
    fn(**daemon)
  File "/home/narate/cron/ldms-test/LDMS_Test.py", line 1003, in start_ldmsd
    cond_timedwait(_check_listen, 5)
  File "/home/narate/cron/ldms-test/LDMS_Test.py", line 2604, in cond_timedwait
    if cond():
  File "/home/narate/cron/ldms-test/LDMS_Test.py", line 1001, in _check_listen
    rc, out = self.exec_run(grp_cmd)
  File "/home/narate/cron/ldms-test/runtime/docker.py", line 144, in exec_run
    return self._exec_run(cmd, environment=env, user=user)
  File "/home/narate/cron/ldms-test/runtime/docker.py", line 148, in _exec_run
    (rc, out) = self.obj.exec_run(*args, **kwargs)
  File "/usr/lib/python3.6/site-packages/docker/models/containers.py", line 200, in exec_run
    demux=demux
  File "/usr/lib/python3.6/site-packages/docker/utils/decorators.py", line 19, in wrapped
    return f(self, resource_id, *args, **kwargs)
  File "/usr/lib/python3.6/site-packages/docker/api/exec_api.py", line 169, in exec_start
    return self._read_from_socket(res, stream, tty=tty, demux=demux)
  File "/usr/lib/python3.6/site-packages/docker/api/client.py", line 400, in _read_from_socket
    socket = self._get_raw_response_socket(response)
  File "/usr/lib/python3.6/site-packages/docker/api/client.py", line 311, in _get_raw_response_socket
    self._raise_for_status(response)
  File "/usr/lib/python3.6/site-packages/docker/api/client.py", line 263, in _raise_for_status
    raise create_api_error_from_http_exception(e)
  File "/usr/lib/python3.6/site-packages/docker/errors.py", line 31, in create_api_error_from_http_exception
    raise cls(e, response=response, explanation=explanation)
docker.errors.APIError: 500 Server Error: Internal Server Error ("Container aa8c35e2b48c3940b4e34fd72ce791c9f1645f3a46544ff20d6a26f7fdcf4020 is not running: Removal In Progress")
2023-07-08 00:58:31,221 TADA INFO assertion 1, Add an updater with a negative interval: skipped
2023-07-08 00:58:31,221 TADA INFO assertion 2, Add an updater with a zero interval: skipped
2023-07-08 00:58:31,221 TADA INFO assertion 3, Add an updater with an alphabet interval: skipped
2023-07-08 00:58:31,221 TADA INFO assertion 4, Add an updater with a negative offset: skipped
2023-07-08 00:58:31,221 TADA INFO assertion 5, Add an updater with an alphabet offset: skipped
2023-07-08 00:58:31,221 TADA INFO assertion 6, Add an updater without an offset: skipped
2023-07-08 00:58:31,222 TADA INFO assertion 7, Add an updater with a valid offset: skipped
2023-07-08 00:58:31,222 TADA INFO assertion 8, Add an updater with an existing name: skipped
2023-07-08 00:58:31,222 TADA INFO test updtr_add test ended
Error in atexit._run_exitfuncs:
Traceback (most recent call last):
  File "/usr/lib/python3.6/site-packages/docker/api/client.py", line 261, in _raise_for_status
    response.raise_for_status()
  File "/usr/lib/python3.6/site-packages/requests/models.py", line 941, in raise_for_status
    raise HTTPError(http_error_msg, response=self)
requests.exceptions.HTTPError: 500 Server Error: Internal Server Error for url: http+docker://localhost/v1.35/networks/sl0dpnqvmjxrzaljaoezdejc7

During handling of the above exception, another exception occurred:

Traceback (most recent call last):
  File "/usr/lib/python3.6/site-packages/docker/api/client.py", line 263, in _raise_for_status
    raise create_api_error_from_http_exception(e)
  File "/usr/lib/python3.6/site-packages/docker/errors.py", line 31, in create_api_error_from_http_exception
    raise cls(e, response=response, explanation=explanation)
docker.errors.APIError: 500 Server Error: Internal Server Error ("network sl0dpnqvmjxrzaljaoezdejc7 not found")
